<?xml version="1.0" ?>
<!-- =================================================================================== -->
<!-- |    This document was autogenerated by xacro from wam_arm.urdf.xacro             | -->
<!-- |    EDITING THIS FILE BY HAND IS NOT RECOMMENDED                                 | -->
<!-- =================================================================================== -->
<robot name="wam" xmlns:xacro="http://www.ros.org/wiki/xacro">
  <!-- Import all Gazebo-customization elements, including Gazebo colors -->
  <!-- ros_control plugin -->
  <gazebo>
    <plugin filename="libgazebo_ros_control.so" name="ros_control">
      <robotNamespace>/wam</robotNamespace>
      <controlPeriod>0.001</controlPeriod>
      <robotSimType>gazebo_ros_control/DefaultRobotHWSim</robotSimType>
    </plugin>
  </gazebo>
  <gazebo reference="wam_link1">
    <material>Gazebo/White</material>
    <gravity>true</gravity>
  </gazebo>
  <gazebo reference="wam_link2">
    <material>Gazebo/Grey</material>
    <gravity>true</gravity>
  </gazebo>
  <gazebo reference="wam_link3">
    <material>Gazebo/Grey</material>
    <gravity>true</gravity>
  </gazebo>
  <gazebo reference="wam_link4">
    <material>Gazebo/Grey</material>
    <gravity>true</gravity>
  </gazebo>
  <gazebo reference="wam_link5">
    <material>Gazebo/Grey</material>
    <gravity>true</gravity>
  </gazebo>
  <gazebo reference="wam_link6">
    <material>Gazebo/Grey</material>
    <gravity>true</gravity>
  </gazebo>
  <gazebo reference="wam_link7">
    <material>Gazebo/Grey</material>
    <gravity>true</gravity>
  </gazebo>
  <!-- Constants for robot dimensions -->
  <!-- BARRETT WAM ARM -->
  <!-- BASE_LINK (RED) -->
  <link name="wam_base_link">
    <inertial>
      <mass value="5.0"/>
      <origin xyz="0 0 0"/>
      <inertia ixx="5.0" ixy="0.0" ixz="0.0" iyy="5.0" iyz="0.0" izz="5.0"/>
    </inertial>
    <visual>
      <origin rpy="0 0 0" xyz="0 0 0"/>
      <geometry>
        <mesh filename="package://wam_description/meshes/wambase.dae"/>
      </geometry>
    </visual>
    <collision>
      <origin rpy="0 0 0 " xyz="0 0 0"/>
      <geometry>
        <mesh filename="package://wam_description/meshes/wambase.dae"/>
      </geometry>
    </collision>
  </link>
  <!-- joint name="j0_joint" type="fixed">
     <origin xyz="0 0 0" rpy="0 0 0" />
     <parent link="wam_base_link"/>
     <child link="wambase_link"/>
    <axis xyz="0 0 0" />
  </joint -->
  <!-- WAM ARM -->
  <link name="wam_link1">
    <inertial>
      <mass value="2.3936"/>
      <origin rpy="0 0 0" xyz="0.0 0.0 0.0"/>
      <inertia ixx="1.0" ixy="0.0" ixz="0.0" iyy="1.0" iyz="0.0" izz="1.0"/>
    </inertial>
    <visual>
      <origin rpy="0 0 0" xyz="0.0 0.0 0.0"/>
      <geometry name="wam_link1_visual">
        <mesh filename="package://wam_description/meshes/wam1.dae" scale="1.0 1.0 1.0"/>
      </geometry>
      <material name="Grey">
        <color rgba="0.75 0.75 0.75 1.0"/>
      </material>
    </visual>
    <collision>
      <origin rpy="0 0 0" xyz="0.0 0.0 0.0"/>
      <geometry name="wam_link1_collision">
        <mesh filename="package://wam_description/meshes/wam1.dae" scale="1.0 1.0 1.0"/>
      </geometry>
      <contact_coefficients kd="1.0" kp="1000.0" mu="0"/>
    </collision>
  </link>
  <joint name="j1_joint" type="revolute">
    <parent link="wam_base_link"/>
    <child link="wam_link1"/>
    <!-- origin xyz="0.125 0 0.55" rpy="0 0 0" / -->
    <origin rpy="0 0 0" xyz="0.0 0 0.0"/>
    <axis xyz="0 0 1"/>
    <limit effort="30.0" lower="-2.6" upper="2.6" velocity="2.0"/>
    <dynamics damping="100.0" friction="0.0"/>
  </joint>
  <transmission name="j1_transmission">
    <type>transmission_interface/SimpleTransmission</type>
    <joint name="j1_joint"/>
    <actuator name="j1">
      <hardwareInterface>EffortJointInterface</hardwareInterface>
      <mechanicalReduction>1</mechanicalReduction>
      <motorTorqueConstant>1</motorTorqueConstant>
    </actuator>
  </transmission>
  <link name="wam_link2">
    <inertial>
      <origin rpy="0 0 0" xyz="0 0 0"/>
      <mass value="1.8487"/>
      <inertia ixx="1.0" ixy="0.0" ixz="0.0" iyy="0.1" iyz="0.0" izz="0.1"/>
    </inertial>
    <visual>
      <origin rpy="0 0 0" xyz="0.0 0.0 0.0"/>
      <geometry name="wam_link2_visual">
        <mesh filename="package://wam_description/meshes/wam2.dae" scale="1.0 1.0 1.0"/>
      </geometry>
      <material name="Grey">
        <color rgba="0.75 0.75 0.75 1.0"/>
      </material>
    </visual>
    <collision>
      <origin rpy="0 0 0" xyz="0.0 0.0 0.0"/>
      <geometry name="wam_link2_collision">
        <mesh filename="package://wam_description/meshes/wam2.dae" scale="1.0 1.0 1.0"/>
      </geometry>
      <contact_coefficients kd="1.0" kp="1000.0" mu="0"/>
    </collision>
  </link>
  <joint name="j2_joint" type="revolute">
    <parent link="wam_link1"/>
    <child link="wam_link2"/>
    <origin rpy="0 0 0" xyz="0.0 0.0 0.0"/>
    <axis xyz="0 1 0"/>
    <limit effort="30.0" lower="-2.0" upper="2.0" velocity="2.0"/>
    <dynamics damping="100.0" friction="0.0"/>
  </joint>
  <transmission name="j2_transmission">
    <type>transmission_interface/SimpleTransmission</type>
    <joint name="j2_joint"/>
    <actuator name="j2">
      <hardwareInterface>EffortJointInterface</hardwareInterface>
      <mechanicalReduction>1</mechanicalReduction>
      <motorTorqueConstant>1</motorTorqueConstant>
    </actuator>
  </transmission>
  <link name="wam_link3">
    <inertial>
      <mass value="0.43"/>
      <origin rpy="0 0 0" xyz="0 0 0.225"/>
      <inertia ixx="1.0" ixy="0.0" ixz="0.0" iyy="0.1" iyz="0.0" izz="0.1"/>
    </inertial>
    <visual>
      <origin rpy="0 0 0" xyz="0.0 0.0 0.0"/>
      <geometry name="wam_link3_visual">
        <mesh filename="package://wam_description/meshes/wam3.dae" scale="1.0 1.0 1.0"/>
      </geometry>
      <material name="Grey">
        <color rgba="0.75 0.75 0.75 1.0"/>
      </material>
    </visual>
    <collision>
      <origin rpy="0 0 0" xyz="0.0 0.0 0.0"/>
      <geometry name="wam_link3_collision">
        <mesh filename="package://wam_description/meshes/wam3.dae" scale="1.0 1.0 1.0"/>
      </geometry>
      <contact_coefficients kd="1.0" kp="1000.0" mu="0"/>
    </collision>
  </link>
  <joint name="j3_joint" type="revolute">
    <parent link="wam_link2"/>
    <child link="wam_link3"/>
    <origin rpy="0 0 0" xyz="0.0 0.0 0.0"/>
    <axis xyz="0 0 1"/>
    <limit effort="30.0" lower="-2.8" upper="2.8" velocity="2.0"/>
    <dynamics damping="100.0" friction="0.0"/>
  </joint>
  <transmission name="j3_transmission">
    <type>transmission_interface/SimpleTransmission</type>
    <joint name="j3_joint"/>
    <actuator name="j3">
      <hardwareInterface>EffortJointInterface</hardwareInterface>
      <mechanicalReduction>1</mechanicalReduction>
      <motorTorqueConstant>1</motorTorqueConstant>
    </actuator>
  </transmission>
  <link name="wam_link4">
    <inertial>
      <mass value="0.52"/>
      <origin rpy="0 0 0" xyz="-0.045 -0.15 0"/>
      <inertia ixx="1.0" ixy="0.0" ixz="0.0" iyy="0.1" iyz="0.0" izz="0.1"/>
    </inertial>
    <visual>
      <origin rpy="0 0 0" xyz="0.0 0.0 0.0"/>
      <geometry name="wam_link4_visual">
        <mesh filename="package://wam_description/meshes/wam4.dae" scale="1.0 1.0 1.0"/>
      </geometry>
      <material name="Grey">
        <color rgba="0.75 0.75 0.75 1.0"/>
      </material>
    </visual>
    <collision>
      <origin rpy="0 0 0" xyz="0.0 0.0 0.0"/>
      <geometry name="wam_link4_collision">
        <mesh filename="package://wam_description/meshes/wam4.dae" scale="1.0 1.0 1.0"/>
      </geometry>
      <contact_coefficients kd="1.0" kp="1000.0" mu="0"/>
    </collision>
  </link>
  <joint name="j4_joint" type="revolute">
    <parent link="wam_link3"/>
    <child link="wam_link4"/>
    <origin rpy="-1.57079632679 0 0" xyz="0.045 0.0 0.55"/>
    <axis xyz="0 0 1"/>
    <limit effort="30.0" lower="-0.9" upper="2.8" velocity="2.0"/>
    <dynamics damping="100.0" friction="0.0"/>
  </joint>
  <transmission name="j4_transmission">
    <type>transmission_interface/SimpleTransmission</type>
    <joint name="j4_joint"/>
    <actuator name="j4">
      <hardwareInterface>EffortJointInterface</hardwareInterface>
      <mechanicalReduction>1</mechanicalReduction>
      <motorTorqueConstant>1</motorTorqueConstant>
    </actuator>
  </transmission>
  <link name="wam_link5">
    <inertial>
      <origin rpy="0 0 0" xyz="0 0 0"/>
      <mass value="0.076675"/>
      <inertia ixx="1.0" ixy="0.0" ixz="0.0" iyy="0.1" iyz="0.0" izz="0.1"/>
    </inertial>
    <visual>
      <origin rpy="0 0 0" xyz="0.0 0.0 0.0"/>
      <geometry name="wam_link5_visual">
        <mesh filename="package://wam_description/meshes/wam5.dae" scale="1.0 1.0 1.0"/>
      </geometry>
      <material name="Grey">
        <color rgba="0.75 0.75 0.75 1.0"/>
      </material>
    </visual>
    <collision>
      <origin rpy="0 0 0" xyz="0.0 0.0 0.0"/>
      <geometry name="wam_link5_collision">
        <mesh filename="package://wam_description/meshes/wam5.dae" scale="1.0 1.0 1.0"/>
      </geometry>
      <contact_coefficients kd="1.0" kp="1000.0" mu="0"/>
    </collision>
  </link>
  <joint name="j5_joint" type="revolute">
    <parent link="wam_link4"/>
    <child link="wam_link5"/>
    <origin rpy="1.57079632679 0 0" xyz="-0.045 -0.3 0.0"/>
    <axis xyz="0 0 1"/>
    <limit effort="30.0" lower="-4.8" upper="1.3" velocity="2.0"/>
    <dynamics damping="100.0" friction="0.0"/>
  </joint>
  <transmission name="j5_transmission">
    <type>transmission_interface/SimpleTransmission</type>
    <joint name="j5_joint"/>
    <actuator name="j5">
      <hardwareInterface>EffortJointInterface</hardwareInterface>
      <mechanicalReduction>1</mechanicalReduction>
      <motorTorqueConstant>1</motorTorqueConstant>
    </actuator>
  </transmission>
  <link name="wam_link6">
    <inertial>
      <origin rpy="0 0 0" xyz="0 0 0"/>
      <mass value="0.10695"/>
      <inertia ixx="1.0" ixy="0.0" ixz="0.0" iyy="0.1" iyz="0.0" izz="0.1"/>
    </inertial>
    <visual>
      <origin rpy="0 0 0" xyz="0.0 0.0 0.0"/>
      <geometry name="wam_link6_visual">
        <mesh filename="package://wam_description/meshes/wam6.dae" scale="1.0 1.0 1.0"/>
      </geometry>
      <material name="Grey">
        <color rgba="0.75 0.75 0.75 1.0"/>
      </material>
    </visual>
    <collision>
      <origin rpy="0 0 0" xyz="0.0 0.0 0.0"/>
      <geometry name="wam_link6_collision">
        <mesh filename="package://wam_description/meshes/wam6.dae" scale="1.0 1.0 1.0"/>
      </geometry>
      <contact_coefficients kd="1.0" kp="1000.0" mu="0"/>
    </collision>
  </link>
  <joint name="j6_joint" type="revolute">
    <parent link="wam_link5"/>
    <child link="wam_link6"/>
    <origin rpy="-1.57079632679 0 0" xyz="0.0 0.0 0.0"/>
    <axis xyz="0 0 1"/>
    <limit effort="30.0" lower="-1.6" upper="1.6" velocity="2.0"/>
    <dynamics damping="100.0" friction="0.0"/>
  </joint>
  <transmission name="j6_transmission">
    <type>transmission_interface/SimpleTransmission</type>
    <joint name="j6_joint"/>
    <actuator name="j6">
      <hardwareInterface>EffortJointInterface</hardwareInterface>
      <mechanicalReduction>1</mechanicalReduction>
      <motorTorqueConstant>1</motorTorqueConstant>
    </actuator>
  </transmission>
  <link name="wam_link7">
    <inertial>
      <origin rpy="0 0 0" xyz="0 0 0"/>
      <mass value="0.013925"/>
      <inertia ixx="1.0" ixy="0.0" ixz="0.0" iyy="0.1" iyz="0.0" izz="0.1"/>
    </inertial>
    <visual>
      <origin rpy="0 0 0" xyz="0.0 0.0 0.0"/>
      <geometry name="wam_link7_visual">
        <mesh filename="package://wam_description/meshes/wam7.dae" scale="1.0 1.0 1.0"/>
      </geometry>
      <material name="Grey">
        <color rgba="0.75 0.75 0.75 1.0"/>
      </material>
    </visual>
    <collision>
      <origin rpy="0 0 0" xyz="0.0 0.0 0.0"/>
      <geometry name="wam_link7_collision">
        <mesh filename="package://wam_description/meshes/wam7.dae" scale="1.0 1.0 1.0"/>
        <!--                <box size="0.10 0.10 0.10"/> -->
      </geometry>
      <contact_coefficients kd="1.0" kp="1000.0" mu="0"/>
    </collision>
  </link>
  <joint name="j7_joint" type="revolute">
    <parent link="wam_link6"/>
    <child link="wam_link7"/>
    <origin rpy="1.57079632679 0 0" xyz="0.0 0.0 0.0"/>
    <axis xyz="0 0 1"/>
    <limit effort="30.0" lower="-2.2" upper="2.2" velocity="2.0"/>
    <!--  <safety_controller k_velocity="0.5"/>-->
    <dynamics damping="100.0" friction="0.0"/>
  </joint>
  <transmission name="j7_transmission">
    <type>transmission_interface/SimpleTransmission</type>
    <joint name="j7_joint"/>
    <actuator name="j7">
      <hardwareInterface>EffortJointInterface</hardwareInterface>
      <mechanicalReduction>1</mechanicalReduction>
      <motorTorqueConstant>1</motorTorqueConstant>
    </actuator>
  </transmission>
  <link name="wam_tcp"/>
  <joint name="wamtcp_fix" type="fixed">
    <parent link="wam_link7"/>
    <child link="wam_tcp"/>
    <origin rpy="0 0 0" xyz="0.0 0.0 0.2"/>
  </joint>
  <!-- GRIPPER -->
  <!-- joint name="wam_gripper_joint" type="fixed">
    <origin rpy="0 0 1.57075" xyz="0 0 0.065"/>
    <parent link="wam_link7"/>
    <child link="gripper_base_link"/>
  </joint -->
</robot>
